Workbook

Sheet GENERAL SUMMARY
B2: SUMMARY
B11: DATE | D11: PROJECT NAME | E11: PROJECT LOCATION
B12: ='DETAILED ESTIMATE'!B15 -> 46304 | D12: ='DETAILED ESTIMATE'!E15 -> FIFTH THIRD BANK WATSON BLVD | E12: ='DETAILED ESTIMATE'!J15 -> 2711 WATSON BOULEVARD WARNER ROBINS, GA 31093
D13: ='DETAILED ESTIMATE'!E16 -> GROSS AREA: 2000 SF
B15: LINE NO. | C15: CSI DIV. | D15: DESCRIPTION | E15: TOTAL LABOR HOURS | F15: MATERIAL COST | G15: LABOR COST | H15: TOTAL COST
B17: =IF(H17<>"",1+MAX($B$15:B15),"") | C17: ='DETAILED ESTIMATE'!C19 -> 0
B18: =IF(H18<>"",1+MAX($B$15:B17),"") -> 1 | C18: ='DETAILED ESTIMATE'!C20 -> DIV. 01 | D18: =VLOOKUP($C18,'DETAILED ESTIMATE'!$C$20:$R$1258,2,0) -> GENERAL REQUIREMENTS | E18: =VLOOKUP($C18,'DETAILED ESTIMATE'!$C$20:$R$1258,9,0) -> 0 HRS | F18: =(VLOOKUP($C18,'DETAILED ESTIMATE'!$C$20:$R$1258,7,0))+'DETAILED ESTIMATE'!$Q$7*(VLOOKUP($C18,'DETAILED ESTIMATE'!$C$20:$R$1258,7,0))+'DETAILED ESTIMATE'!$Q$9*(VLOOKUP($C18,'DETAILED ESTIMATE'!$C$20:$R$1258,7,0))+'DETAILED ESTIMATE'!$Q$10*((VLOOKUP($C18,'DETAILED ESTIMATE'!$C$20:$R$1258,7,0))+'DETAILED ESTIMATE'!$Q$7*(VLOOKUP($C18,'DETAILED ESTIMATE'!$C$20:$R$1258,7,0))+'DETAILED ESTIMATE'!$Q$9*(VLOOKUP($C18,'DETAILED ESTIMATE'!$C$20:$R$1258,7,0)))+'DETAILED ESTIMATE'!$Q$11*(VLOOKUP($C18,'DETAILED ESTIMATE'!$C$20:$R$1258,7,0)) -> 0 | G18: =(VLOOKUP($C18,'DETAILED ESTIMATE'!$C$20:$R$1258,14,0))+'DETAILED ESTIMATE'!$Q$8*(VLOOKUP($C18,'DETAILED ESTIMATE'!$C$20:$R$1258,14,0))+'DETAILED ESTIMATE'!$Q$9*(VLOOKUP($C18,'DETAILED ESTIMATE'!$C$20:$R$1258,14,0))+'DETAILED ESTIMATE'!$Q$10*((VLOOKUP($C18,'DETAILED ESTIMATE'!$C$20:$R$1258,14,0))+'DETAILED ESTIMATE'!$Q$8*(VLOOKUP($C18,'DETAILED ESTIMATE'!$C$20:$R$1258,14,0))+'DETAILED ESTIMATE'!$Q$9*(VLOOKUP($C18,'DETAILED ESTIMATE'!$C$20:$R$1258,14,0)))+'DETAILED ESTIMATE'!$Q$11*(VLOOKUP($C18,'DETAILED ESTIMATE'!$C$20:$R$1258,14,0)) -> 164818.5 | H18: =VLOOKUP($C18,'DETAILED ESTIMATE'!$C$20:$R$1258,16,0) -> 164818.5
B19: =IF(H19<>"",1+MAX($B$15:B18),"") -> 2 | C19: ='DETAILED ESTIMATE'!C24 -> DIV. 02 | D19: =VLOOKUP($C19,'DETAILED ESTIMATE'!$C$20:$R$1258,2,0) -> EXISTING CONDITIONS | E19: =VLOOKUP($C19,'DETAILED ESTIMATE'!$C$20:$R$1258,9,0) -> 2747 HRS | F19: =(VLOOKUP($C19,'DETAILED ESTIMATE'!$C$20:$R$1258,7,0))+'DETAILED ESTIMATE'!$Q$7*(VLOOKUP($C19,'DETAILED ESTIMATE'!$C$20:$R$1258,7,0))+'DETAILED ESTIMATE'!$Q$9*(VLOOKUP($C19,'DETAILED ESTIMATE'!$C$20:$R$1258,7,0))+'DETAILED ESTIMATE'!$Q$10*((VLOOKUP($C19,'DETAILED ESTIMATE'!$C$20:$R$1258,7,0))+'DETAILED ESTIMATE'!$Q$7*(VLOOKUP($C19,'DETAILED ESTIMATE'!$C$20:$R$1258,7,0))+'DETAILED ESTIMATE'!$Q$9*(VLOOKUP($C19,'DETAILED ESTIMATE'!$C$20:$R$1258,7,0)))+'DETAILED ESTIMATE'!$Q$11*(VLOOKUP($C19,'DETAILED ESTIMATE'!$C$20:$R$1258,7,0)) -> 0 | G19: =(VLOOKUP($C19,'DETAILED ESTIMATE'!$C$20:$R$1258,14,0))+'DETAILED ESTIMATE'!$Q$8*(VLOOKUP($C19,'DETAILED ESTIMATE'!$C$20:$R$1258,14,0))+'DETAILED ESTIMATE'!$Q$9*(VLOOKUP($C19,'DETAILED ESTIMATE'!$C$20:$R$1258,14,0))+'DETAILED ESTIMATE'!$Q$10*((VLOOKUP($C19,'DETAILED ESTIMATE'!$C$20:$R$1258,14,0))+'DETAILED ESTIMATE'!$Q$8*(VLOOKUP($C19,'DETAILED ESTIMATE'!$C$20:$R$1258,14,0))+'DETAILED ESTIMATE'!$Q$9*(VLOOKUP($C19,'DETAILED ESTIMATE'!$C$20:$R$1258,14,0)))+'DETAILED ESTIMATE'!$Q$11*(VLOOKUP($C19,'DETAILED ESTIMATE'!$C$20:$R$1258,14,0)) -> 172757.77 | H19: =VLOOKUP($C19,'DETAILED ESTIMATE'!$C$20:$R$1258,16,0) -> 172757.77
B20: =IF(H20<>"",1+MAX($B$15:B19),"") -> 3 | C20: ='DETAILED ESTIMATE'!C42 -> DIV. 03 | D20: =VLOOKUP($C20,'DETAILED ESTIMATE'!$C$20:$R$1258,2,0) -> CONCRETE | E20: =VLOOKUP($C20,'DETAILED ESTIMATE'!$C$20:$R$1258,9,0) -> 413 HRS | F20: =(VLOOKUP($C20,'DETAILED ESTIMATE'!$C$20:$R$1258,7,0))+'DETAILED ESTIMATE'!$Q$7*(VLOOKUP($C20,'DETAILED ESTIMATE'!$C$20:$R$1258,7,0))+'DETAILED ESTIMATE'!$Q$9*(VLOOKUP($C20,'DETAILED ESTIMATE'!$C$20:$R$1258,7,0))+'DETAILED ESTIMATE'!$Q$10*((VLOOKUP($C20,'DETAILED ESTIMATE'!$C$20:$R$1258,7,0))+'DETAILED ESTIMATE'!$Q$7*(VLOOKUP($C20,'DETAILED ESTIMATE'!$C$20:$R$1258,7,0))+'DETAILED ESTIMATE'!$Q$9*(VLOOKUP($C20,'DETAILED ESTIMATE'!$C$20:$R$1258,7,0)))+'DETAILED ESTIMATE'!$Q$11*(VLOOKUP($C20,'DETAILED ESTIMATE'!$C$20:$R$1258,7,0)) -> 26726.059 | G20: =(VLOOKUP($C20,'DETAILED ESTIMATE'!$C$20:$R$1258,14,0))+'DETAILED ESTIMATE'!$Q$8*(VLOOKUP($C20,'DETAILED ESTIMATE'!$C$20:$R$1258,14,0))+'DETAILED ESTIMATE'!$Q$9*(VLOOKUP($C20,'DETAILED ESTIMATE'!$C$20:$R$1258,14,0))+'DETAILED ESTIMATE'!$Q$10*((VLOOKUP($C20,'DETAILED ESTIMATE'!$C$20:$R$1258,14,0))+'DETAILED ESTIMATE'!$Q$8*(VLOOKUP($C20,'DETAILED ESTIMATE'!$C$20:$R$1258,14,0))+'DETAILED ESTIMATE'!$Q$9*(VLOOKUP($C20,'DETAILED ESTIMATE'!$C$20:$R$1258,14,0)))+'DETAILED ESTIMATE'!$Q$11*(VLOOKUP($C20,'DETAILED ESTIMATE'!$C$20:$R$1258,14,0)) -> 21916.874 | H20: =VLOOKUP($C20,'DETAILED ESTIMATE'!$C$20:$R$1258,16,0) -> 48642.933
B21: =IF(H21<>"",1+MAX($B$15:B20),"") -> 4 | C21: ='DETAILED ESTIMATE'!C75 -> DIV. 04 | D21: =VLOOKUP($C21,'DETAILED ESTIMATE'!$C$20:$R$1258,2,0) -> MASONRY | E21: =VLOOKUP($C21,'DETAILED ESTIMATE'!$C$20:$R$1258,9,0) -> 224 HRS | F21: =(VLOOKUP($C21,'DETAILED ESTIMATE'!$C$20:$R$1258,7,0))+'DETAILED ESTIMATE'!$Q$7*(VLOOKUP($C21,'DETAILED ESTIMATE'!$C$20:$R$1258,7,0))+'DETAILED ESTIMATE'!$Q$9*(VLOOKUP($C21,'DETAILED ESTIMATE'!$C$20:$R$1258,7,0))+'DETAILED ESTIMATE'!$Q$10*((VLOOKUP($C21,'DETAILED ESTIMATE'!$C$20:$R$1258,7,0))+'DETAILED ESTIMATE'!$Q$7*(VLOOKUP($C21,'DETAILED ESTIMATE'!$C$20:$R$1258,7,0))+'DETAILED ESTIMATE'!$Q$9*(VLOOKUP($C21,'DETAILED ESTIMATE'!$C$20:$R$1258,7,0)))+'DETAILED ESTIMATE'!$Q$11*(VLOOKUP($C21,'DETAILED ESTIMATE'!$C$20:$R$1258,7,0)) -> 6160.8637 | G21: =(VLOOKUP($C21,'DETAILED ESTIMATE'!$C$20:$R$1258,14,0))+'DETAILED ESTIMATE'!$Q$8*(VLOOKUP($C21,'DETAILED ESTIMATE'!$C$20:$R$1258,14,0))+'DETAILED ESTIMATE'!$Q$9*(VLOOKUP($C21,'DETAILED ESTIMATE'!$C$20:$R$1258,14,0))+'DETAILED ESTIMATE'!$Q$10*((VLOOKUP($C21,'DETAILED ESTIMATE'!$C$20:$R$1258,14,0))+'DETAILED ESTIMATE'!$Q$8*(VLOOKUP($C21,'DETAILED ESTIMATE'!$C$20:$R$1258,14,0))+'DETAILED ESTIMATE'!$Q$9*(VLOOKUP($C21,'DETAILED ESTIMATE'!$C$20:$R$1258,14,0)))+'DETAILED ESTIMATE'!$Q$11*(VLOOKUP($C21,'DETAILED ESTIMATE'!$C$20:$R$1258,14,0)) -> 11128.622 | H21: =VLOOKUP($C21,'DETAILED ESTIMATE'!$C$20:$R$1258,16,0) -> 17289.486
B22: =IF(H22<>"",1+MAX($B$15:B21),"") -> 5 | C22: ='DETAILED ESTIMATE'!C90 -> DIV. 05 | D22: =VLOOKUP($C22,'DETAILED ESTIMATE'!$C$20:$R$1258,2,0) -> METALS | E22: =VLOOKUP($C22,'DETAILED ESTIMATE'!$C$20:$R$1258,9,0) -> 777 HRS | F22: =(VLOOKUP($C22,'DETAILED ESTIMATE'!$C$20:$R$1258,7,0))+'DETAILED ESTIMATE'!$Q$7*(VLOOKUP($C22,'DETAILED ESTIMATE'!$C$20:$R$1258,7,0))+'DETAILED ESTIMATE'!$Q$9*(VLOOKUP($C22,'DETAILED ESTIMATE'!$C$20:$R$1258,7,0))+'DETAILED ESTIMATE'!$Q$10*((VLOOKUP($C22,'DETAILED ESTIMATE'!$C$20:$R$1258,7,0))+'DETAILED ESTIMATE'!$Q$7*(VLOOKUP($C22,'DETAILED ESTIMATE'!$C$20:$R$1258,7,0))+'DETAILED ESTIMATE'!$Q$9*(VLOOKUP($C22,'DETAILED ESTIMATE'!$C$20:$R$1258,7,0)))+'DETAILED ESTIMATE'!$Q$11*(VLOOKUP($C22,'DETAILED ESTIMATE'!$C$20:$R$1258,7,0)) -> 90177.103 | G22: =(VLOOKUP($C22,'DETAILED ESTIMATE'!$C$20:$R$1258,14,0))+'DETAILED ESTIMATE'!$Q$8*(VLOOKUP($C22,'DETAILED ESTIMATE'!$C$20:$R$1258,14,0))+'DETAILED ESTIMATE'!$Q$9*(VLOOKUP($C22,'DETAILED ESTIMATE'!$C$20:$R$1258,14,0))+'DETAILED ESTIMATE'!$Q$10*((VLOOKUP($C22,'DETAILED ESTIMATE'!$C$20:$R$1258,14,0))+'DETAILED ESTIMATE'!$Q$8*(VLOOKUP($C22,'DETAILED ESTIMATE'!$C$20:$R$1258,14,0))+'DETAILED ESTIMATE'!$Q$9*(VLOOKUP($C22,'DETAILED ESTIMATE'!$C$20:$R$1258,14,0)))+'DETAILED ESTIMATE'!$Q$11*(VLOOKUP($C22,'DETAILED ESTIMATE'!$C$20:$R$1258,14,0)) -> 58048.816 | H22: =VLOOKUP($C22,'DETAILED ESTIMATE'!$C$20:$R$1258,16,0) -> 148225.92
B23: =IF(H23<>"",1+MAX($B$15:B22),"") -> 6 | C23: ='DETAILED ESTIMATE'!C155 -> DIV. 06 | D23: =VLOOKUP($C23,'DETAILED ESTIMATE'!$C$20:$R$1258,2,0) -> WOOD, PLASTICS AND COMPOSITES | E23: =VLOOKUP($C23,'DETAILED ESTIMATE'!$C$20:$R$1258,9,0) -> 284 HRS | F23: =(VLOOKUP($C23,'DETAILED ESTIMATE'!$C$20:$R$1258,7,0))+'DETAILED ESTIMATE'!$Q$7*(VLOOKUP($C23,'DETAILED ESTIMATE'!$C$20:$R$1258,7,0))+'DETAILED ESTIMATE'!$Q$9*(VLOOKUP($C23,'DETAILED ESTIMATE'!$C$20:$R$1258,7,0))+'DETAILED ESTIMATE'!$Q$10*((VLOOKUP($C23,'DETAILED ESTIMATE'!$C$20:$R$1258,7,0))+'DETAILED ESTIMATE'!$Q$7*(VLOOKUP($C23,'DETAILED ESTIMATE'!$C$20:$R$1258,7,0))+'DETAILED ESTIMATE'!$Q$9*(VLOOKUP($C23,'DETAILED ESTIMATE'!$C$20:$R$1258,7,0)))+'DETAILED ESTIMATE'!$Q$11*(VLOOKUP($C23,'DETAILED ESTIMATE'!$C$20:$R$1258,7,0)) -> 66000.408 | G23: =(VLOOKUP($C23,'DETAILED ESTIMATE'!$C$20:$R$1258,14,0))+'DETAILED ESTIMATE'!$Q$8*(VLOOKUP($C23,'DETAILED ESTIMATE'!$C$20:$R$1258,14,0))+'DETAILED ESTIMATE'!$Q$9*(VLOOKUP($C23,'DETAILED ESTIMATE'!$C$20:$R$1258,14,0))+'DETAILED ESTIMATE'!$Q$10*((VLOOKUP($C23,'DETAILED ESTIMATE'!$C$20:$R$1258,14,0))+'DETAILED ESTIMATE'!$Q$8*(VLOOKUP($C23,'DETAILED ESTIMATE'!$C$20:$R$1258,14,0))+'DETAILED ESTIMATE'!$Q$9*(VLOOKUP($C23,'DETAILED ESTIMATE'!$C$20:$R$1258,14,0)))+'DETAILED ESTIMATE'!$Q$11*(VLOOKUP($C23,'DETAILED ESTIMATE'!$C$20:$R$1258,14,0)) -> 15734.352 | H23: =VLOOKUP($C23,'DETAILED ESTIMATE'!$C$20:$R$1258,16,0) -> 81734.759
B24: =IF(H24<>"",1+MAX($B$15:B23),"") -> 7 | C24: ='DETAILED ESTIMATE'!C266 -> DIV. 07 | D24: =VLOOKUP($C24,'DETAILED ESTIMATE'!$C$20:$R$1258,2,0) -> THERMAL AND MOISTURE PROTECTION | E24: =VLOOKUP($C24,'DETAILED ESTIMATE'!$C$20:$R$1258,9,0) -> 855 HRS | F24: =(VLOOKUP($C24,'DETAILED ESTIMATE'!$C$20:$R$1258,7,0))+'DETAILED ESTIMATE'!$Q$7*(VLOOKUP($C24,'DETAILED ESTIMATE'!$C$20:$R$1258,7,0))+'DETAILED ESTIMATE'!$Q$9*(VLOOKUP($C24,'DETAILED ESTIMATE'!$C$20:$R$1258,7,0))+'DETAILED ESTIMATE'!$Q$10*((VLOOKUP($C24,'DETAILED ESTIMATE'!$C$20:$R$1258,7,0))+'DETAILED ESTIMATE'!$Q$7*(VLOOKUP($C24,'DETAILED ESTIMATE'!$C$20:$R$1258,7,0))+'DETAILED ESTIMATE'!$Q$9*(VLOOKUP($C24,'DETAILED ESTIMATE'!$C$20:$R$1258,7,0)))+'DETAILED ESTIMATE'!$Q$11*(VLOOKUP($C24,'DETAILED ESTIMATE'!$C$20:$R$1258,7,0)) -> 72497.177 | G24: =(VLOOKUP($C24,'DETAILED ESTIMATE'!$C$20:$R$1258,14,0))+'DETAILED ESTIMATE'!$Q$8*(VLOOKUP($C24,'DETAILED ESTIMATE'!$C$20:$R$1258,14,0))+'DETAILED ESTIMATE'!$Q$9*(VLOOKUP($C24,'DETAILED ESTIMATE'!$C$20:$R$1258,14,0))+'DETAILED ESTIMATE'!$Q$10*((VLOOKUP($C24,'DETAILED ESTIMATE'!$C$20:$R$1258,14,0))+'DETAILED ESTIMATE'!$Q$8*(VLOOKUP($C24,'DETAILED ESTIMATE'!$C$20:$R$1258,14,0))+'DETAILED ESTIMATE'!$Q$9*(VLOOKUP($C24,'DETAILED ESTIMATE'!$C$20:$R$1258,14,0)))+'DETAILED ESTIMATE'!$Q$11*(VLOOKUP($C24,'DETAILED ESTIMATE'!$C$20:$R$1258,14,0)) -> 44027.775 | H24: =VLOOKUP($C24,'DETAILED ESTIMATE'!$C$20:$R$1258,16,0) -> 116524.95
B25: =IF(H25<>"",1+MAX($B$15:B24),"") -> 8 | C25: ='DETAILED ESTIMATE'!C344 -> DIV. 08 | D25: =VLOOKUP($C25,'DETAILED ESTIMATE'!$C$20:$R$1258,2,0) -> OPENINGS | E25: =VLOOKUP($C25,'DETAILED ESTIMATE'!$C$20:$R$1258,9,0) -> 213 HRS | F25: =(VLOOKUP($C25,'DETAILED ESTIMATE'!$C$20:$R$1258,7,0))+'DETAILED ESTIMATE'!$Q$7*(VLOOKUP($C25,'DETAILED ESTIMATE'!$C$20:$R$1258,7,0))+'DETAILED ESTIMATE'!$Q$9*(VLOOKUP($C25,'DETAILED ESTIMATE'!$C$20:$R$1258,7,0))+'DETAILED ESTIMATE'!$Q$10*((VLOOKUP($C25,'DETAILED ESTIMATE'!$C$20:$R$1258,7,0))+'DETAILED ESTIMATE'!$Q$7*(VLOOKUP($C25,'DETAILED ESTIMATE'!$C$20:$R$1258,7,0))+'DETAILED ESTIMATE'!$Q$9*(VLOOKUP($C25,'DETAILED ESTIMATE'!$C$20:$R$1258,7,0)))+'DETAILED ESTIMATE'!$Q$11*(VLOOKUP($C25,'DETAILED ESTIMATE'!$C$20:$R$1258,7,0)) -> 100158.24 | G25: =(VLOOKUP($C25,'DETAILED ESTIMATE'!$C$20:$R$1258,14,0))+'DETAILED ESTIMATE'!$Q$8*(VLOOKUP($C25,'DETAILED ESTIMATE'!$C$20:$R$1258,14,0))+'DETAILED ESTIMATE'!$Q$9*(VLOOKUP($C25,'DETAILED ESTIMATE'!$C$20:$R$1258,14,0))+'DETAILED ESTIMATE'!$Q$10*((VLOOKUP($C25,'DETAILED ESTIMATE'!$C$20:$R$1258,14,0))+'DETAILED ESTIMATE'!$Q$8*(VLOOKUP($C25,'DETAILED ESTIMATE'!$C$20:$R$1258,14,0))+'DETAILED ESTIMATE'!$Q$9*(VLOOKUP($C25,'DETAILED ESTIMATE'!$C$20:$R$1258,14,0)))+'DETAILED ESTIMATE'!$Q$11*(VLOOKUP($C25,'DETAILED ESTIMATE'!$C$20:$R$1258,14,0)) -> 11901.292 | H25: =VLOOKUP($C25,'DETAILED ESTIMATE'!$C$20:$R$1258,16,0) -> 112059.54
B26: =IF(H26<>"",1+MAX($B$15:B25),"") -> 9 | C26: ='DETAILED ESTIMATE'!C392 -> DIV. 09 | D26: =VLOOKUP($C26,'DETAILED ESTIMATE'!$C$20:$R$1258,2,0) -> FINISHES | E26: =VLOOKUP($C26,'DETAILED ESTIMATE'!$C$20:$R$1258,9,0) -> 1025 HRS | F26: =(VLOOKUP($C26,'DETAILED ESTIMATE'!$C$20:$R$1258,7,0))+'DETAILED ESTIMATE'!$Q$7*(VLOOKUP($C26,'DETAILED ESTIMATE'!$C$20:$R$1258,7,0))+'DETAILED ESTIMATE'!$Q$9*(VLOOKUP($C26,'DETAILED ESTIMATE'!$C$20:$R$1258,7,0))+'DETAILED ESTIMATE'!$Q$10*((VLOOKUP($C26,'DETAILED ESTIMATE'!$C$20:$R$1258,7,0))+'DETAILED ESTIMATE'!$Q$7*(VLOOKUP($C26,'DETAILED ESTIMATE'!$C$20:$R$1258,7,0))+'DETAILED ESTIMATE'!$Q$9*(VLOOKUP($C26,'DETAILED ESTIMATE'!$C$20:$R$1258,7,0)))+'DETAILED ESTIMATE'!$Q$11*(VLOOKUP($C26,'DETAILED ESTIMATE'!$C$20:$R$1258,7,0)) -> 85410.622 | G26: =(VLOOKUP($C26,'DETAILED ESTIMATE'!$C$20:$R$1258,14,0))+'DETAILED ESTIMATE'!$Q$8*(VLOOKUP($C26,'DETAILED ESTIMATE'!$C$20:$R$1258,14,0))+'DETAILED ESTIMATE'!$Q$9*(VLOOKUP($C26,'DETAILED ESTIMATE'!$C$20:$R$1258,14,0))+'DETAILED ESTIMATE'!$Q$10*((VLOOKUP($C26,'DETAILED ESTIMATE'!$C$20:$R$1258,14,0))+'DETAILED ESTIMATE'!$Q$8*(VLOOKUP($C26,'DETAILED ESTIMATE'!$C$20:$R$1258,14,0))+'DETAILED ESTIMATE'!$Q$9*(VLOOKUP($C26,'DETAILED ESTIMATE'!$C$20:$R$1258,14,0)))+'DETAILED ESTIMATE'!$Q$11*(VLOOKUP($C26,'DETAILED ESTIMATE'!$C$20:$R$1258,14,0)) -> 54520.862 | H26: =VLOOKUP($C26,'DETAILED ESTIMATE'!$C$20:$R$1258,16,0) -> 139931.48
B27: =IF(H27<>"",1+MAX($B$15:B26),"") -> 10 | C27: ='DETAILED ESTIMATE'!C547 -> DIV. 10 | D27: =VLOOKUP($C27,'DETAILED ESTIMATE'!$C$20:$R$1258,2,0) -> SPECIALTIES | E27: =VLOOKUP($C27,'DETAILED ESTIMATE'!$C$20:$R$1258,9,0) -> 15 HRS | F27: =(VLOOKUP($C27,'DETAILED ESTIMATE'!$C$20:$R$1258,7,0))+'DETAILED ESTIMATE'!$Q$7*(VLOOKUP($C27,'DETAILED ESTIMATE'!$C$20:$R$1258,7,0))+'DETAILED ESTIMATE'!$Q$9*(VLOOKUP($C27,'DETAILED ESTIMATE'!$C$20:$R$1258,7,0))+'DETAILED ESTIMATE'!$Q$10*((VLOOKUP($C27,'DETAILED ESTIMATE'!$C$20:$R$1258,7,0))+'DETAILED ESTIMATE'!$Q$7*(VLOOKUP($C27,'DETAILED ESTIMATE'!$C$20:$R$1258,7,0))+'DETAILED ESTIMATE'!$Q$9*(VLOOKUP($C27,'DETAILED ESTIMATE'!$C$20:$R$1258,7,0)))+'DETAILED ESTIMATE'!$Q$11*(VLOOKUP($C27,'DETAILED ESTIMATE'!$C$20:$R$1258,7,0)) -> 3690.2857 | G27: =(VLOOKUP($C27,'DETAILED ESTIMATE'!$C$20:$R$1258,14,0))+'DETAILED ESTIMATE'!$Q$8*(VLOOKUP($C27,'DETAILED ESTIMATE'!$C$20:$R$1258,14,0))+'DETAILED ESTIMATE'!$Q$9*(VLOOKUP($C27,'DETAILED ESTIMATE'!$C$20:$R$1258,14,0))+'DETAILED ESTIMATE'!$Q$10*((VLOOKUP($C27,'DETAILED ESTIMATE'!$C$20:$R$1258,14,0))+'DETAILED ESTIMATE'!$Q$8*(VLOOKUP($C27,'DETAILED ESTIMATE'!$C$20:$R$1258,14,0))+'DETAILED ESTIMATE'!$Q$9*(VLOOKUP($C27,'DETAILED ESTIMATE'!$C$20:$R$1258,14,0)))+'DETAILED ESTIMATE'!$Q$11*(VLOOKUP($C27,'DETAILED ESTIMATE'!$C$20:$R$1258,14,0)) -> 833.69235 | H27: =VLOOKUP($C27,'DETAILED ESTIMATE'!$C$20:$R$1258,16,0) -> 4523.9781
B28: =IF(H28<>"",1+MAX($B$15:B27),"") -> 11 | C28: ='DETAILED ESTIMATE'!C575 -> DIV. 11 | D28: =VLOOKUP($C28,'DETAILED ESTIMATE'!$C$20:$R$1258,2,0) -> EQUIPMENT | E28: =VLOOKUP($C28,'DETAILED ESTIMATE'!$C$20:$R$1258,9,0) -> 27 HRS | F28: =(VLOOKUP($C28,'DETAILED ESTIMATE'!$C$20:$R$1258,7,0))+'DETAILED ESTIMATE'!$Q$7*(VLOOKUP($C28,'DETAILED ESTIMATE'!$C$20:$R$1258,7,0))+'DETAILED ESTIMATE'!$Q$9*(VLOOKUP($C28,'DETAILED ESTIMATE'!$C$20:$R$1258,7,0))+'DETAILED ESTIMATE'!$Q$10*((VLOOKUP($C28,'DETAILED ESTIMATE'!$C$20:$R$1258,7,0))+'DETAILED ESTIMATE'!$Q$7*(VLOOKUP($C28,'DETAILED ESTIMATE'!$C$20:$R$1258,7,0))+'DETAILED ESTIMATE'!$Q$9*(VLOOKUP($C28,'DETAILED ESTIMATE'!$C$20:$R$1258,7,0)))+'DETAILED ESTIMATE'!$Q$11*(VLOOKUP($C28,'DETAILED ESTIMATE'!$C$20:$R$1258,7,0)) -> 28358.181 | G28: =(VLOOKUP($C28,'DETAILED ESTIMATE'!$C$20:$R$1258,14,0))+'DETAILED ESTIMATE'!$Q$8*(VLOOKUP($C28,'DETAILED ESTIMATE'!$C$20:$R$1258,14,0))+'DETAILED ESTIMATE'!$Q$9*(VLOOKUP($C28,'DETAILED ESTIMATE'!$C$20:$R$1258,14,0))+'DETAILED ESTIMATE'!$Q$10*((VLOOKUP($C28,'DETAILED ESTIMATE'!$C$20:$R$1258,14,0))+'DETAILED ESTIMATE'!$Q$8*(VLOOKUP($C28,'DETAILED ESTIMATE'!$C$20:$R$1258,14,0))+'DETAILED ESTIMATE'!$Q$9*(VLOOKUP($C28,'DETAILED ESTIMATE'!$C$20:$R$1258,14,0)))+'DETAILED ESTIMATE'!$Q$11*(VLOOKUP($C28,'DETAILED ESTIMATE'!$C$20:$R$1258,14,0)) -> 1625.946 | H28: =VLOOKUP($C28,'DETAILED ESTIMATE'!$C$20:$R$1258,16,0) -> 29984.127
B29: =IF(H29<>"",1+MAX($B$15:B28),"") -> 12 | C29: ='DETAILED ESTIMATE'!C589 -> DIV. 12 | D29: =VLOOKUP($C29,'DETAILED ESTIMATE'!$C$20:$R$1258,2,0) -> FURNISHINGS | E29: =VLOOKUP($C29,'DETAILED ESTIMATE'!$C$20:$R$1258,9,0) -> 205 HRS | F29: =(VLOOKUP($C29,'DETAILED ESTIMATE'!$C$20:$R$1258,7,0))+'DETAILED ESTIMATE'!$Q$7*(VLOOKUP($C29,'DETAILED ESTIMATE'!$C$20:$R$1258,7,0))+'DETAILED ESTIMATE'!$Q$9*(VLOOKUP($C29,'DETAILED ESTIMATE'!$C$20:$R$1258,7,0))+'DETAILED ESTIMATE'!$Q$10*((VLOOKUP($C29,'DETAILED ESTIMATE'!$C$20:$R$1258,7,0))+'DETAILED ESTIMATE'!$Q$7*(VLOOKUP($C29,'DETAILED ESTIMATE'!$C$20:$R$1258,7,0))+'DETAILED ESTIMATE'!$Q$9*(VLOOKUP($C29,'DETAILED ESTIMATE'!$C$20:$R$1258,7,0)))+'DETAILED ESTIMATE'!$Q$11*(VLOOKUP($C29,'DETAILED ESTIMATE'!$C$20:$R$1258,7,0)) -> 39362.729 | G29: =(VLOOKUP($C29,'DETAILED ESTIMATE'!$C$20:$R$1258,14,0))+'DETAILED ESTIMATE'!$Q$8*(VLOOKUP($C29,'DETAILED ESTIMATE'!$C$20:$R$1258,14,0))+'DETAILED ESTIMATE'!$Q$9*(VLOOKUP($C29,'DETAILED ESTIMATE'!$C$20:$R$1258,14,0))+'DETAILED ESTIMATE'!$Q$10*((VLOOKUP($C29,'DETAILED ESTIMATE'!$C$20:$R$1258,14,0))+'DETAILED ESTIMATE'!$Q$8*(VLOOKUP($C29,'DETAILED ESTIMATE'!$C$20:$R$1258,14,0))+'DETAILED ESTIMATE'!$Q$9*(VLOOKUP($C29,'DETAILED ESTIMATE'!$C$20:$R$1258,14,0)))+'DETAILED ESTIMATE'!$Q$11*(VLOOKUP($C29,'DETAILED ESTIMATE'!$C$20:$R$1258,14,0)) -> 10903.676 | H29: =VLOOKUP($C29,'DETAILED ESTIMATE'!$C$20:$R$1258,16,0) -> 50266.405
B30: =IF(H30<>"",1+MAX($B$15:B29),"") -> 13 | C30: ='DETAILED ESTIMATE'!C660 -> DIV. 22 | D30: =VLOOKUP($C30,'DETAILED ESTIMATE'!$C$20:$R$1258,2,0) -> PLUMBING | E30: =VLOOKUP($C30,'DETAILED ESTIMATE'!$C$20:$R$1258,9,0) -> 381 HRS | F30: =(VLOOKUP($C30,'DETAILED ESTIMATE'!$C$20:$R$1258,7,0))+'DETAILED ESTIMATE'!$Q$7*(VLOOKUP($C30,'DETAILED ESTIMATE'!$C$20:$R$1258,7,0))+'DETAILED ESTIMATE'!$Q$9*(VLOOKUP($C30,'DETAILED ESTIMATE'!$C$20:$R$1258,7,0))+'DETAILED ESTIMATE'!$Q$10*((VLOOKUP($C30,'DETAILED ESTIMATE'!$C$20:$R$1258,7,0))+'DETAILED ESTIMATE'!$Q$7*(VLOOKUP($C30,'DETAILED ESTIMATE'!$C$20:$R$1258,7,0))+'DETAILED ESTIMATE'!$Q$9*(VLOOKUP($C30,'DETAILED ESTIMATE'!$C$20:$R$1258,7,0)))+'DETAILED ESTIMATE'!$Q$11*(VLOOKUP($C30,'DETAILED ESTIMATE'!$C$20:$R$1258,7,0)) -> 49734.179 | G30: =(VLOOKUP($C30,'DETAILED ESTIMATE'!$C$20:$R$1258,14,0))+'DETAILED ESTIMATE'!$Q$8*(VLOOKUP($C30,'DETAILED ESTIMATE'!$C$20:$R$1258,14,0))+'DETAILED ESTIMATE'!$Q$9*(VLOOKUP($C30,'DETAILED ESTIMATE'!$C$20:$R$1258,14,0))+'DETAILED ESTIMATE'!$Q$10*((VLOOKUP($C30,'DETAILED ESTIMATE'!$C$20:$R$1258,14,0))+'DETAILED ESTIMATE'!$Q$8*(VLOOKUP($C30,'DETAILED ESTIMATE'!$C$20:$R$1258,14,0))+'DETAILED ESTIMATE'!$Q$9*(VLOOKUP($C30,'DETAILED ESTIMATE'!$C$20:$R$1258,14,0)))+'DETAILED ESTIMATE'!$Q$11*(VLOOKUP($C30,'DETAILED ESTIMATE'!$C$20:$R$1258,14,0)) -> 23664.705 | H30: =VLOOKUP($C30,'DETAILED ESTIMATE'!$C$20:$R$1258,16,0) -> 73398.884
B31: =IF(H31<>"",1+MAX($B$15:B30),"") -> 14 | C31: ='DETAILED ESTIMATE'!C739 -> DIV. 23 | D31: =VLOOKUP($C31,'DETAILED ESTIMATE'!$C$20:$R$1258,2,0) -> HEATING, VENTILATION AND AIR CONDITIONING (HVAC) | E31: =VLOOKUP($C31,'DETAILED ESTIMATE'!$C$20:$R$1258,9,0) -> 320 HRS | F31: =(VLOOKUP($C31,'DETAILED ESTIMATE'!$C$20:$R$1258,7,0))+'DETAILED ESTIMATE'!$Q$7*(VLOOKUP($C31,'DETAILED ESTIMATE'!$C$20:$R$1258,7,0))+'DETAILED ESTIMATE'!$Q$9*(VLOOKUP($C31,'DETAILED ESTIMATE'!$C$20:$R$1258,7,0))+'DETAILED ESTIMATE'!$Q$10*((VLOOKUP($C31,'DETAILED ESTIMATE'!$C$20:$R$1258,7,0))+'DETAILED ESTIMATE'!$Q$7*(VLOOKUP($C31,'DETAILED ESTIMATE'!$C$20:$R$1258,7,0))+'DETAILED ESTIMATE'!$Q$9*(VLOOKUP($C31,'DETAILED ESTIMATE'!$C$20:$R$1258,7,0)))+'DETAILED ESTIMATE'!$Q$11*(VLOOKUP($C31,'DETAILED ESTIMATE'!$C$20:$R$1258,7,0)) -> 58771.329 | G31: =(VLOOKUP($C31,'DETAILED ESTIMATE'!$C$20:$R$1258,14,0))+'DETAILED ESTIMATE'!$Q$8*(VLOOKUP($C31,'DETAILED ESTIMATE'!$C$20:$R$1258,14,0))+'DETAILED ESTIMATE'!$Q$9*(VLOOKUP($C31,'DETAILED ESTIMATE'!$C$20:$R$1258,14,0))+'DETAILED ESTIMATE'!$Q$10*((VLOOKUP($C31,'DETAILED ESTIMATE'!$C$20:$R$1258,14,0))+'DETAILED ESTIMATE'!$Q$8*(VLOOKUP($C31,'DETAILED ESTIMATE'!$C$20:$R$1258,14,0))+'DETAILED ESTIMATE'!$Q$9*(VLOOKUP($C31,'DETAILED ESTIMATE'!$C$20:$R$1258,14,0)))+'DETAILED ESTIMATE'!$Q$11*(VLOOKUP($C31,'DETAILED ESTIMATE'!$C$20:$R$1258,14,0)) -> 19414.527 | H31: =VLOOKUP($C31,'DETAILED ESTIMATE'!$C$20:$R$1258,16,0) -> 78185.855
B32: =IF(H32<>"",1+MAX($B$15:B31),"") -> 15 | C32: ='DETAILED ESTIMATE'!C822 -> DIV. 26 | D32: =VLOOKUP($C32,'DETAILED ESTIMATE'!$C$20:$R$1258,2,0) -> ELECTRICAL | E32: =VLOOKUP($C32,'DETAILED ESTIMATE'!$C$20:$R$1258,9,0) -> 759 HRS | F32: =(VLOOKUP($C32,'DETAILED ESTIMATE'!$C$20:$R$1258,7,0))+'DETAILED ESTIMATE'!$Q$7*(VLOOKUP($C32,'DETAILED ESTIMATE'!$C$20:$R$1258,7,0))+'DETAILED ESTIMATE'!$Q$9*(VLOOKUP($C32,'DETAILED ESTIMATE'!$C$20:$R$1258,7,0))+'DETAILED ESTIMATE'!$Q$10*((VLOOKUP($C32,'DETAILED ESTIMATE'!$C$20:$R$1258,7,0))+'DETAILED ESTIMATE'!$Q$7*(VLOOKUP($C32,'DETAILED ESTIMATE'!$C$20:$R$1258,7,0))+'DETAILED ESTIMATE'!$Q$9*(VLOOKUP($C32,'DETAILED ESTIMATE'!$C$20:$R$1258,7,0)))+'DETAILED ESTIMATE'!$Q$11*(VLOOKUP($C32,'DETAILED ESTIMATE'!$C$20:$R$1258,7,0)) -> 236144.19 | G32: =(VLOOKUP($C32,'DETAILED ESTIMATE'!$C$20:$R$1258,14,0))+'DETAILED ESTIMATE'!$Q$8*(VLOOKUP($C32,'DETAILED ESTIMATE'!$C$20:$R$1258,14,0))+'DETAILED ESTIMATE'!$Q$9*(VLOOKUP($C32,'DETAILED ESTIMATE'!$C$20:$R$1258,14,0))+'DETAILED ESTIMATE'!$Q$10*((VLOOKUP($C32,'DETAILED ESTIMATE'!$C$20:$R$1258,14,0))+'DETAILED ESTIMATE'!$Q$8*(VLOOKUP($C32,'DETAILED ESTIMATE'!$C$20:$R$1258,14,0))+'DETAILED ESTIMATE'!$Q$9*(VLOOKUP($C32,'DETAILED ESTIMATE'!$C$20:$R$1258,14,0)))+'DETAILED ESTIMATE'!$Q$11*(VLOOKUP($C32,'DETAILED ESTIMATE'!$C$20:$R$1258,14,0)) -> 49138.347 | H32: =VLOOKUP($C32,'DETAILED ESTIMATE'!$C$20:$R$1258,16,0) -> 285282.53
B33: =IF(H33<>"",1+MAX($B$15:B32),"") -> 16 | C33: ='DETAILED ESTIMATE'!C970 -> DIV. 28 | D33: =VLOOKUP($C33,'DETAILED ESTIMATE'!$C$20:$R$1258,2,0) -> ELECTRONIC SAFETY AND SECURITY | E33: =VLOOKUP($C33,'DETAILED ESTIMATE'!$C$20:$R$1258,9,0) -> 140 HRS | F33: =(VLOOKUP($C33,'DETAILED ESTIMATE'!$C$20:$R$1258,7,0))+'DETAILED ESTIMATE'!$Q$7*(VLOOKUP($C33,'DETAILED ESTIMATE'!$C$20:$R$1258,7,0))+'DETAILED ESTIMATE'!$Q$9*(VLOOKUP($C33,'DETAILED ESTIMATE'!$C$20:$R$1258,7,0))+'DETAILED ESTIMATE'!$Q$10*((VLOOKUP($C33,'DETAILED ESTIMATE'!$C$20:$R$1258,7,0))+'DETAILED ESTIMATE'!$Q$7*(VLOOKUP($C33,'DETAILED ESTIMATE'!$C$20:$R$1258,7,0))+'DETAILED ESTIMATE'!$Q$9*(VLOOKUP($C33,'DETAILED ESTIMATE'!$C$20:$R$1258,7,0)))+'DETAILED ESTIMATE'!$Q$11*(VLOOKUP($C33,'DETAILED ESTIMATE'!$C$20:$R$1258,7,0)) -> 30241.835 | G33: =(VLOOKUP($C33,'DETAILED ESTIMATE'!$C$20:$R$1258,14,0))+'DETAILED ESTIMATE'!$Q$8*(VLOOKUP($C33,'DETAILED ESTIMATE'!$C$20:$R$1258,14,0))+'DETAILED ESTIMATE'!$Q$9*(VLOOKUP($C33,'DETAILED ESTIMATE'!$C$20:$R$1258,14,0))+'DETAILED ESTIMATE'!$Q$10*((VLOOKUP($C33,'DETAILED ESTIMATE'!$C$20:$R$1258,14,0))+'DETAILED ESTIMATE'!$Q$8*(VLOOKUP($C33,'DETAILED ESTIMATE'!$C$20:$R$1258,14,0))+'DETAILED ESTIMATE'!$Q$9*(VLOOKUP($C33,'DETAILED ESTIMATE'!$C$20:$R$1258,14,0)))+'DETAILED ESTIMATE'!$Q$11*(VLOOKUP($C33,'DETAILED ESTIMATE'!$C$20:$R$1258,14,0)) -> 8932.1232 | H33: =VLOOKUP($C33,'DETAILED ESTIMATE'!$C$20:$R$1258,16,0) -> 39173.959
B34: =IF(H34<>"",1+MAX($B$15:B33),"") -> 17 | C34: ='DETAILED ESTIMATE'!C1022 -> DIV. 31 | D34: =VLOOKUP($C34,'DETAILED ESTIMATE'!$C$20:$R$1258,2,0) -> EARTHWORK | E34: =VLOOKUP($C34,'DETAILED ESTIMATE'!$C$20:$R$1258,9,0) -> 294 HRS | F34: =(VLOOKUP($C34,'DETAILED ESTIMATE'!$C$20:$R$1258,7,0))+'DETAILED ESTIMATE'!$Q$7*(VLOOKUP($C34,'DETAILED ESTIMATE'!$C$20:$R$1258,7,0))+'DETAILED ESTIMATE'!$Q$9*(VLOOKUP($C34,'DETAILED ESTIMATE'!$C$20:$R$1258,7,0))+'DETAILED ESTIMATE'!$Q$10*((VLOOKUP($C34,'DETAILED ESTIMATE'!$C$20:$R$1258,7,0))+'DETAILED ESTIMATE'!$Q$7*(VLOOKUP($C34,'DETAILED ESTIMATE'!$C$20:$R$1258,7,0))+'DETAILED ESTIMATE'!$Q$9*(VLOOKUP($C34,'DETAILED ESTIMATE'!$C$20:$R$1258,7,0)))+'DETAILED ESTIMATE'!$Q$11*(VLOOKUP($C34,'DETAILED ESTIMATE'!$C$20:$R$1258,7,0)) -> 0 | G34: =(VLOOKUP($C34,'DETAILED ESTIMATE'!$C$20:$R$1258,14,0))+'DETAILED ESTIMATE'!$Q$8*(VLOOKUP($C34,'DETAILED ESTIMATE'!$C$20:$R$1258,14,0))+'DETAILED ESTIMATE'!$Q$9*(VLOOKUP($C34,'DETAILED ESTIMATE'!$C$20:$R$1258,14,0))+'DETAILED ESTIMATE'!$Q$10*((VLOOKUP($C34,'DETAILED ESTIMATE'!$C$20:$R$1258,14,0))+'DETAILED ESTIMATE'!$Q$8*(VLOOKUP($C34,'DETAILED ESTIMATE'!$C$20:$R$1258,14,0))+'DETAILED ESTIMATE'!$Q$9*(VLOOKUP($C34,'DETAILED ESTIMATE'!$C$20:$R$1258,14,0)))+'DETAILED ESTIMATE'!$Q$11*(VLOOKUP($C34,'DETAILED ESTIMATE'!$C$20:$R$1258,14,0)) -> 12926.431 | H34: =VLOOKUP($C34,'DETAILED ESTIMATE'!$C$20:$R$1258,16,0) -> 12926.431
B35: =IF(H35<>"",1+MAX($B$15:B34),"") -> 18 | C35: ='DETAILED ESTIMATE'!C1033 -> DIV. 32 | D35: =VLOOKUP($C35,'DETAILED ESTIMATE'!$C$20:$R$1258,2,0) -> EXTERIOR IMPROVEMENT | E35: =VLOOKUP($C35,'DETAILED ESTIMATE'!$C$20:$R$1258,9,0) -> 3077 HRS | F35: =(VLOOKUP($C35,'DETAILED ESTIMATE'!$C$20:$R$1258,7,0))+'DETAILED ESTIMATE'!$Q$7*(VLOOKUP($C35,'DETAILED ESTIMATE'!$C$20:$R$1258,7,0))+'DETAILED ESTIMATE'!$Q$9*(VLOOKUP($C35,'DETAILED ESTIMATE'!$C$20:$R$1258,7,0))+'DETAILED ESTIMATE'!$Q$10*((VLOOKUP($C35,'DETAILED ESTIMATE'!$C$20:$R$1258,7,0))+'DETAILED ESTIMATE'!$Q$7*(VLOOKUP($C35,'DETAILED ESTIMATE'!$C$20:$R$1258,7,0))+'DETAILED ESTIMATE'!$Q$9*(VLOOKUP($C35,'DETAILED ESTIMATE'!$C$20:$R$1258,7,0)))+'DETAILED ESTIMATE'!$Q$11*(VLOOKUP($C35,'DETAILED ESTIMATE'!$C$20:$R$1258,7,0)) -> 302445.07 | G35: =(VLOOKUP($C35,'DETAILED ESTIMATE'!$C$20:$R$1258,14,0))+'DETAILED ESTIMATE'!$Q$8*(VLOOKUP($C35,'DETAILED ESTIMATE'!$C$20:$R$1258,14,0))+'DETAILED ESTIMATE'!$Q$9*(VLOOKUP($C35,'DETAILED ESTIMATE'!$C$20:$R$1258,14,0))+'DETAILED ESTIMATE'!$Q$10*((VLOOKUP($C35,'DETAILED ESTIMATE'!$C$20:$R$1258,14,0))+'DETAILED ESTIMATE'!$Q$8*(VLOOKUP($C35,'DETAILED ESTIMATE'!$C$20:$R$1258,14,0))+'DETAILED ESTIMATE'!$Q$9*(VLOOKUP($C35,'DETAILED ESTIMATE'!$C$20:$R$1258,14,0)))+'DETAILED ESTIMATE'!$Q$11*(VLOOKUP($C35,'DETAILED ESTIMATE'!$C$20:$R$1258,14,0)) -> 168459.86 | H35: =VLOOKUP($C35,'DETAILED ESTIMATE'!$C$20:$R$1258,16,0) -> 470904.93
B36: =IF(H36<>"",1+MAX($B$15:B35),"") -> 19 | C36: ='DETAILED ESTIMATE'!C1221 -> DIV. 33 | D36: =VLOOKUP($C36,'DETAILED ESTIMATE'!$C$20:$R$1258,2,0) -> UTILITIES | E36: =VLOOKUP($C36,'DETAILED ESTIMATE'!$C$20:$R$1258,9,0) -> 1612 HRS | F36: =(VLOOKUP($C36,'DETAILED ESTIMATE'!$C$20:$R$1258,7,0))+'DETAILED ESTIMATE'!$Q$7*(VLOOKUP($C36,'DETAILED ESTIMATE'!$C$20:$R$1258,7,0))+'DETAILED ESTIMATE'!$Q$9*(VLOOKUP($C36,'DETAILED ESTIMATE'!$C$20:$R$1258,7,0))+'DETAILED ESTIMATE'!$Q$10*((VLOOKUP($C36,'DETAILED ESTIMATE'!$C$20:$R$1258,7,0))+'DETAILED ESTIMATE'!$Q$7*(VLOOKUP($C36,'DETAILED ESTIMATE'!$C$20:$R$1258,7,0))+'DETAILED ESTIMATE'!$Q$9*(VLOOKUP($C36,'DETAILED ESTIMATE'!$C$20:$R$1258,7,0)))+'DETAILED ESTIMATE'!$Q$11*(VLOOKUP($C36,'DETAILED ESTIMATE'!$C$20:$R$1258,7,0)) -> 71124.259 | G36: =(VLOOKUP($C36,'DETAILED ESTIMATE'!$C$20:$R$1258,14,0))+'DETAILED ESTIMATE'!$Q$8*(VLOOKUP($C36,'DETAILED ESTIMATE'!$C$20:$R$1258,14,0))+'DETAILED ESTIMATE'!$Q$9*(VLOOKUP($C36,'DETAILED ESTIMATE'!$C$20:$R$1258,14,0))+'DETAILED ESTIMATE'!$Q$10*((VLOOKUP($C36,'DETAILED ESTIMATE'!$C$20:$R$1258,14,0))+'DETAILED ESTIMATE'!$Q$8*(VLOOKUP($C36,'DETAILED ESTIMATE'!$C$20:$R$1258,14,0))+'DETAILED ESTIMATE'!$Q$9*(VLOOKUP($C36,'DETAILED ESTIMATE'!$C$20:$R$1258,14,0)))+'DETAILED ESTIMATE'!$Q$11*(VLOOKUP($C36,'DETAILED ESTIMATE'!$C$20:$R$1258,14,0)) -> 76562.623 | H36: =VLOOKUP($C36,'DETAILED ESTIMATE'!$C$20:$R$1258,16,0) -> 147686.88
B37: =IF(H37<>"",1+MAX($B$15:B36),"")
B38: =IF(H38<>"",1+MAX($B$15:B37),"") -> 20 | D38: TOTAL PROJECT COST AND MANHOURS | E38: =ROUNDUP('DETAILED ESTIMATE'!R13,0) & " " & "HRS" -> 13369 HRS | H38: =SUM(H18:H37) -> 2194319.3
B39: =IF(H39<>"",1+MAX($B$15:B38),"")

Sheet DETAILED ESTIMATE
T1: MAT. FAC. | U1: LAB. FAC.
B2: CONSTRUCTION COST ESTIMATE BREAKDOWN | T2: 0.952 | U2: 0.731
J3: PROPOSED PROJECT AMOUNT
J4: TOTAL MATERIAL COST | R4: =SUM(I20:I1258)/2 -> 907334.95
J5: TOTAL LABOR COST | R5: =SUM(P20:P1258)/2 -> 649836.58
J6: SUBTOTAL | R6: =SUM(R4:R5) -> 1557171.5
J7: SALES TAX | Q7: 0.07 | R7: =R4*Q7 -> 63513.447
J8: LABOR BURDEN | Q8: 0.1 | R8: =R5*Q8 -> 64983.658
J9: OVERHEAD & PROFIT | Q9: 0.25 | R9: =R6*Q9 -> 389292.88
J10: BONDING | Q10: 0.02 | R10: =SUM(R6:R9)*Q10 -> 41499.23
J11: CONTINGENCY / WASTAGE | Q11: 0.05 | R11: =R6*Q11 -> 77858.577
J12: PROPOSED PROJECT AMOUNT | R12: =SUM(R6:R11) -> 2194319.3
J13: TOTAL MANHOURS | R13: =SUM(K21:K1258) -> 13368.127
B14: DATE | D14: SCOPE OF WORK | E14: PROJECT NAME | J14: PROJECT LOCATION
B15: 46304 | D15: COMPLETE GC | E15: FIFTH THIRD BANK WATSON BLVD | J15: 2711 WATSON BOULEVARD WARNER ROBINS, GA 31093
E16: GROSS AREA: 2000 SF
B17: LINE NO. | C17: DWG REF./ CSI SEC. | D17: ITEM DESCRIPTION | E17: UNIT OF MEASURE | F17: QUANTITY | G17: MATERIAL | J17: LABOR | Q17: LINE TOTAL | R17: TRADE TOTAL W/ S.TAX, O&P
G18: UNIT PRICE | H18: UNIT PRICE | I18: TOTAL COST | J18: UNIT LABOR HOUR | K18: LABOR HOURS | L18: CREW | M18: LABOR RATE | N18: LABOR RATE | O18: UNIT PRICE | P18: TOTAL COST
B19: =IF(F19<>"",1+MAX($B$1:B18),"")
B20: =IF(F20<>"",1+MAX($B$1:B19),"") | C20: DIV. 01 | D20: GENERAL REQUIREMENTS | H20: SUBTOTAL MATERIAL | I20: =SUM(I21:I23) -> 0 | J20: SUBTOTAL LAB. HRS. | K20: =ROUND(SUM(K21:K23),0) & " " & "HRS" -> 0 HRS | O20: SUBTOTAL LABOR | P20: =SUM(P21:P23) -> 115500 | Q20: =SUM(Q21:Q23) -> 115500 | R20: =(Q20)+(I20*$Q$7)+(P20*$Q$8)+(Q20*$Q$9)+($Q$10*((Q20)+(I20*$Q$7)+(P20*$Q$8)+(Q20*$Q$9)))+(Q20*$Q$11) -> 164818.5
H21: =G21*$T$2 -> 0 | I21: =F21*H21 -> 0 | K21: =F21*J21 -> 0 | N21: =M21*$U$2 -> 0 | O21: =J21*N21 -> 0 | P21: =F21*O21 -> 0 | Q21: =I21+P21 -> 0 | R21: =Q21+(I21*$Q$7)+(P21*$Q$8)+(Q21*$Q$9)+(Q21*$Q$11)+($Q$10*(Q21+(I21*$Q$7)+(P21*$Q$8)+(Q21*$Q$9))) -> 0
B22: =IF(F22<>"",1+MAX($B$21:B21),"") -> 1 | D22: PERMITS, SITE SUPERVISION, FINAL CLEANUP & DUMPSTER | E22: LS | F22: 1 | H22: =G22*$T$2 -> 0 | I22: =F22*H22 -> 0 | K22: =F22*J22 -> 0 | N22: =M22*$U$2 -> 0 | O22: 115500 | P22: =F22*O22 -> 115500 | Q22: =I22+P22 -> 115500 | R22: =Q22+(I22*$Q$7)+(P22*$Q$8)+(Q22*$Q$9)+(Q22*$Q$11)+($Q$10*(Q22+(I22*$Q$7)+(P22*$Q$8)+(Q22*$Q$9))) -> 164818.5
B23: =IF(F23<>"",1+MAX($B$21:B22),"") | H23: =G23*$T$2 -> 0 | I23: =F23*H23 -> 0 | K23: =F23*J23 -> 0 | N23: =M23*$U$2 -> 0 | O23: =J23*N23 -> 0 | P23: =F23*O23 -> 0 | Q23: =I23+P23 -> 0 | R23: =Q23+(I23*$Q$7)+(P23*$Q$8)+(Q23*$Q$9)+(Q23*$Q$11)+($Q$10*(Q23+(I23*$Q$7)+(P23*$Q$8)+(Q23*$Q$9))) -> 0
B24: =IF(F24<>"",1+MAX($B$21:B23),"") | C24: DIV. 02 | D24: EXISTING CONDITIONS | H24: SUBTOTAL MATERIAL | I24: =SUM(I25:I40) -> 0 | J24: SUBTOTAL LAB. HRS. | K24: =ROUND(SUM(K25:K40),0) & " " & "HRS" -> 2747 HRS | O24: SUBTOTAL LABOR | P24: =SUM(P25:P40) -> 121063.61 | Q24: =SUM(Q25:Q40) -> 121063.61 | R24: =(Q24)+(I24*$Q$7)+(P24*$Q$8)+(Q24*$Q$9)+($Q$10*((Q24)+(I24*$Q$7)+(P24*$Q$8)+(Q24*$Q$9)))+(Q24*$Q$11) -> 172757.77
B25: =IF(F25<>"",1+MAX($B$21:B24),"") | H25: =G25*$T$2 -> 0 | I25: =F25*H25 -> 0 | K25: =F25*J25 -> 0 | N25: =M25*$U$2 -> 0 | O25: =J25*N25 -> 0 | P25: =F25*O25 -> 0 | Q25: =I25+P25 -> 0 | R25: =Q25+(I25*$Q$7)+(P25*$Q$8)+(Q25*$Q$9)+(Q25*$Q$11)+($Q$10*(Q25+(I25*$Q$7)+(P25*$Q$8)+(Q25*$Q$9))) -> 0
B26: =IF(F26<>"",1+MAX($B$21:B25),"") | D26: DEMOLITION | H26: =G26*$T$2 -> 0 | I26: =F26*H26 -> 0 | K26: =F26*J26 -> 0 | N26: =M26*$U$2 -> 0 | O26: =J26*N26 -> 0 | P26: =F26*O26 -> 0 | Q26: =I26+P26 -> 0 | R26: =Q26+(I26*$Q$7)+(P26*$Q$8)+(Q26*$Q$9)+(Q26*$Q$11)+($Q$10*(Q26+(I26*$Q$7)+(P26*$Q$8)+(Q26*$Q$9))) -> 0
B27: =IF(F27<>"",1+MAX($B$21:B26),"") -> 2 | C27: C-1.0 | D27: 1: REMOVE EXISTING CURB & GUTTER | E27: LF | F27: 987.22 | H27: =G27*$T$2 -> 0 | I27: =F27*H27 -> 0 | J27: 0.165 | K27: =F27*J27 -> 162.8913 | L27: 1 CLAB | M27: 42.1 | N27: =M27*$U$2 -> 30.7751 | O27: =J27*N27 -> 5.0778915 | P27: =F27*O27 -> 5012.996 | Q27: =I27+P27 -> 5012.996 | R27: =Q27+(I27*$Q$7)+(P27*$Q$8)+(Q27*$Q$9)+(Q27*$Q$11)+($Q$10*(Q27+(I27*$Q$7)+(P27*$Q$8)+(Q27*$Q$9))) -> 7153.5454
B28: =IF(F28<>"",1+MAX($B$21:B27),"") -> 3 | D28: 2: REMOVE EXISTING TWO STORY BUILDING STRUCTURE AND FOUNDATION | E28: CFT | F28: =4489*20 -> 89780 | H28: =G28*$T$2 -> 0 | I28: =F28*H28 -> 0 | J28: 0.009 | K28: =F28*J28 -> 808.02 | L28: B-8 | M28: 94.03 | N28: =M28*$U$2 -> 68.73593 | O28: =J28*N28 -> 0.61862337 | P28: =F28*O28 -> 55540.006 | Q28: =I28+P28 -> 55540.006 | R28: =Q28+(I28*$Q$7)+(P28*$Q$8)+(Q28*$Q$9)+(Q28*$Q$11)+($Q$10*(Q28+(I28*$Q$7)+(P28*$Q$8)+(Q28*$Q$9))) -> 79255.589
B29: =IF(F29<>"",1+MAX($B$21:B28),"") -> 4 | D29: 2: REMOVE EXISTING ONE STORY BUILDING STRUCTURE AND FOUNDATION | E29: CFT | F29: =1714*10 -> 17140 | H29: =G29*$T$2 -> 0 | I29: =F29*H29 -> 0 | J29: 0.009 | K29: =F29*J29 -> 154.26 | L29: B-8 | M29: 94.03 | N29: =M29*$U$2 -> 68.73593 | O29: =J29*N29 -> 0.61862337 | P29: =F29*O29 -> 10603.205 | Q29: =I29+P29 -> 10603.205 | R29: =Q29+(I29*$Q$7)+(P29*$Q$8)+(Q29*$Q$9)+(Q29*$Q$11)+($Q$10*(Q29+(I29*$Q$7)+(P29*$Q$8)+(Q29*$Q$9))) -> 15130.773
B30: =IF(F30<>"",1+MAX($B$21:B29),"") -> 5 | D30: 9: REMOVE EXISTING SIDEWALK | E30: SF | F30: 390.17 | H30: =G30*$T$2 -> 0 | I30: =F30*H30 -> 0 | J30: 0.075 | K30: =F30*J30 -> 29.26275 | L30: 1 CLAB | M30: 42.1 | N30: =M30*$U$2 -> 30.7751 | O30: =J30*N30 -> 2.3081325 | P30: =F30*O30 -> 900.56406 | Q30: =I30+P30 -> 900.56406 | R30: =Q30+(I30*$Q$7)+(P30*$Q$8)+(Q30*$Q$9)+(Q30*$Q$11)+($Q$10*(Q30+(I30*$Q$7)+(P30*$Q$8)+(Q30*$Q$9))) -> 1285.1049
B31: =IF(F31<>"",1+MAX($B$21:B30),"") -> 6 | D31: 10: REMOVE EXISTING MONUMENT SIGN | E31: EA | F31: 1 | H31: =G31*$T$2 -> 0 | I31: =F31*H31 -> 0 | J31: 3.5 | K31: =F31*J31 -> 3.5 | L31: 1 CLAB | M31: 42.1 | N31: =M31*$U$2 -> 30.7751 | O31: =J31*N31 -> 107.71285 | P31: =F31*O31 -> 107.71285 | Q31: =I31+P31 -> 107.71285 | R31: =Q31+(I31*$Q$7)+(P31*$Q$8)+(Q31*$Q$9)+(Q31*$Q$11)+($Q$10*(Q31+(I31*$Q$7)+(P31*$Q$8)+(Q31*$Q$9))) -> 153.70624
B32: =IF(F32<>"",1+MAX($B$21:B31),"") -> 7 | D32: 11: REMOVE EXISTING CONCRETE RAMP | E32: SF | F32: 442.37 | H32: =G32*$T$2 -> 0 | I32: =F32*H32 -> 0 | J32: 0.075 | K32: =F32*J32 -> 33.17775 | L32: 1 CLAB | M32: 42.1 | N32: =M32*$U$2 -> 30.7751 | O32: =J32*N32 -> 2.3081325 | P32: =F32*O32 -> 1021.0486 | Q32: =I32+P32 -> 1021.0486 | R32: =Q32+(I32*$Q$7)+(P32*$Q$8)+(Q32*$Q$9)+(Q32*$Q$11)+($Q$10*(Q32+(I32*$Q$7)+(P32*$Q$8)+(Q32*$Q$9))) -> 1457.0363
B33: =IF(F33<>"",1+MAX($B$21:B32),"") -> 8 | D33: 11: REMOVE EXISTING BRICK STAIR STEPS | E33: EA | F33: 7 | H33: =G33*$T$2 -> 0 | I33: =F33*H33 -> 0 | J33: 0.225 | K33: =F33*J33 -> 1.575 | L33: 1 CLAB | M33: 42.1 | N33: =M33*$U$2 -> 30.7751 | O33: =J33*N33 -> 6.9243975 | P33: =F33*O33 -> 48.470783 | Q33: =I33+P33 -> 48.470783 | R33: =Q33+(I33*$Q$7)+(P33*$Q$8)+(Q33*$Q$9)+(Q33*$Q$11)+($Q$10*(Q33+(I33*$Q$7)+(P33*$Q$8)+(Q33*$Q$9))) -> 69.167807
B34: =IF(F34<>"",1+MAX($B$21:B33),"") -> 9 | D34: 7: REMOVE EXISTING PAVEMENT W/ PAVEMENT STRIPING | E34: SF | F34: 19363.57 | H34: =G34*$T$2 -> 0 | I34: =F34*H34 -> 0 | J34: 0.075 | K34: =F34*J34 -> 1452.2677 | L34: 1 CLAB | M34: 42.1 | N34: =M34*$U$2 -> 30.7751 | O34: =J34*N34 -> 2.3081325 | P34: =F34*O34 -> 44693.685 | Q34: =I34+P34 -> 44693.685 | R34: =Q34+(I34*$Q$7)+(P34*$Q$8)+(Q34*$Q$9)+(Q34*$Q$11)+($Q$10*(Q34+(I34*$Q$7)+(P34*$Q$8)+(Q34*$Q$9))) -> 63777.889
B35: =IF(F35<>"",1+MAX($B$21:B34),"") -> 10 | D35: 8: REMOVE EXISTING TREES/VEGETATION | E35: EA | F35: 2 | H35: =G35*$T$2 -> 0 | I35: =F35*H35 -> 0 | J35: 1.95 | K35: =F35*J35 -> 3.9 | L35: 1 CLAB | M35: 42.1 | N35: =M35*$U$2 -> 30.7751 | O35: =J35*N35 -> 60.011445 | P35: =F35*O35 -> 120.02289 | Q35: =I35+P35 -> 120.02289 | R35: =Q35+(I35*$Q$7)+(P35*$Q$8)+(Q35*$Q$9)+(Q35*$Q$11)+($Q$10*(Q35+(I35*$Q$7)+(P35*$Q$8)+(Q35*$Q$9))) -> 171.27266
B36: =IF(F36<>"",1+MAX($B$21:B35),"") -> 11 | D36: 6: REMOVE EXISTING WATER LINE AND ASSOCIATED STRUCTURES | E36: LF | F36: 55.6 | H36: =G36*$T$2 -> 0 | I36: =F36*H36 -> 0 | J36: 0.065 | K36: =F36*J36 -> 3.614 | L36: 1 CLAB | M36: 42.1 | N36: =M36*$U$2 -> 30.7751 | O36: =J36*N36 -> 2.0003815 | P36: =F36*O36 -> 111.22121 | Q36: =I36+P36 -> 111.22121 | R36: =Q36+(I36*$Q$7)+(P36*$Q$8)+(Q36*$Q$9)+(Q36*$Q$11)+($Q$10*(Q36+(I36*$Q$7)+(P36*$Q$8)+(Q36*$Q$9))) -> 158.71267
B37: =IF(F37<>"",1+MAX($B$21:B36),"") -> 12 | D37: 5: REMOVE EXISTING POWER LINE AND ASSOCIATED STRUCTURES | E37: LF | F37: 965.36 | H37: =G37*$T$2 -> 0 | I37: =F37*H37 -> 0 | J37: 0.06 | K37: =F37*J37 -> 57.9216 | L37: 1 CLAB | M37: 42.1 | N37: =M37*$U$2 -> 30.7751 | O37: =J37*N37 -> 1.846506 | P37: =F37*O37 -> 1782.543 | Q37: =I37+P37 -> 1782.543 | R37: =Q37+(I37*$Q$7)+(P37*$Q$8)+(Q37*$Q$9)+(Q37*$Q$11)+($Q$10*(Q37+(I37*$Q$7)+(P37*$Q$8)+(Q37*$Q$9))) -> 2543.6889
B38: =IF(F38<>"",1+MAX($B$21:B37),"") -> 13 | D38: REMOVE EXISTING METAL HANDRAIL | E38: LF | F38: 76.2 | H38: =G38*$T$2 -> 0 | I38: =F38*H38 -> 0 | J38: 0.135 | K38: =F38*J38 -> 10.287 | L38: 1 CLAB | M38: 42.1 | N38: =M38*$U$2 -> 30.7751 | O38: =J38*N38 -> 4.1546385 | P38: =F38*O38 -> 316.58345 | Q38: =I38+P38 -> 316.58345 | R38: =Q38+(I38*$Q$7)+(P38*$Q$8)+(Q38*$Q$9)+(Q38*$Q$11)+($Q$10*(Q38+(I38*$Q$7)+(P38*$Q$8)+(Q38*$Q$9))) -> 451.76459
B39: =IF(F39<>"",1+MAX($B$21:B38),"") -> 14 | D39: 4: REMOVE EXISTING STORM SEWER LINE AND ASSOCIATED STRUCTURES - ASSUMED | E39: LF | F39: 107.11 | H39: =G39*$T$2 -> 0 | I39: =F39*H39 -> 0 | J39: 0.095 | K39: =F39*J39 -> 10.17545 | L39: 1 CLAB | M39: 42.1 | N39: =M39*$U$2 -> 30.7751 | O39: =J39*N39 -> 2.9236345 | P39: =F39*O39 -> 313.15049 | Q39: =I39+P39 -> 313.15049 | R39: =Q39+(I39*$Q$7)+(P39*$Q$8)+(Q39*$Q$9)+(Q39*$Q$11)+($Q$10*(Q39+(I39*$Q$7)+(P39*$Q$8)+(Q39*$Q$9))) -> 446.86575
B40: =IF(F40<>"",1+MAX($B$21:B39),"") -> 15 | D40: 4: REMOVE EXISTING STORM STRUCTURE | E40: EA | F40: 2 | H40: =G40*$T$2 -> 0 | I40: =F40*H40 -> 0 | J40: 8 | K40: =F40*J40 -> 16 | L40: 1 CLAB | M40: 42.1 | N40: =M40*$U$2 -> 30.7751 | O40: =J40*N40 -> 246.2008 | P40: =F40*O40 -> 492.4016 | Q40: =I40+P40 -> 492.4016 | R40: =Q40+(I40*$Q$7)+(P40*$Q$8)+(Q40*$Q$9)+(Q40*$Q$11)+($Q$10*(Q40+(I40*$Q$7)+(P40*$Q$8)+(Q40*$Q$9))) -> 702.65708
...
